Workbook

Sheet Data
A1: Day | B1: Monto | C1: Detalle | D1: Clasificacion | E1: Checker | F1: Check Class | G1: Check Monto
A2: 1 | C2: Luz | D2: Luz | E2: =if(and(F2,G2),1,2) -> 2 | F2: =ISBLANK(D2) -> FALSE | G2: =ISNUMBER(B2) -> FALSE
A3: 1 | B3: 37 | C3: ChatGPT | D3: Otros Personales | E3: =if(and(F3,G3),1,2) -> 2 | F3: =ISBLANK(D3) -> FALSE | G3: =ISNUMBER(B3) -> TRUE
A4: 1 | B4: 95 | C4: Internet | D4: Internet | E4: =if(and(F4,G4),1,2) -> 2 | F4: =ISBLANK(D4) -> FALSE | G4: =ISNUMBER(B4) -> TRUE
A5: 1 | B5: 33 | C5: DogDown Yoga App | D5: Otros Personales | E5: =if(and(F5,G5),1,2) -> 2 | F5: =ISBLANK(D5) -> FALSE | G5: =ISNUMBER(B5) -> TRUE
A6: 1 | B6: 27 | C6: Youtube - Suscripción x2 | D6: Otros Personales | E6: =if(and(F6,G6),1,2) -> 2 | F6: =ISBLANK(D6) -> FALSE | G6: =ISNUMBER(B6) -> TRUE
A7: 1 | B7: 34 | C7: Claude Pro | D7: Otros Personales
A8: 2 | B8: 200.67 | C8: Declaraciones Renta Chile 2026 x2 | D8: Otros Personales
A9: 2 | B9: 90 | C9: Uniqlo - Ropa Pato | D9: Ropa - Accesorios
A10: 2 | B10: 50 | C10: Uniqlo - Regalos | D10: Regalos - Eventos
A11: 2 | B11: 33 | C11: Haketama - Ramen Chermise | D11: Almuerzo
A12: 2 | B12: 6 | C12: Brazzos - Pudin | D12: Almuerzo
A13: 2 | B13: 88 | C13: Kmart - Pijamas | D13: Ropa - Accesorios
A14: 2 | B14: 110 | C14: Wollies | D14: Super
A15: 2 | B15: 6 | C15: Parking Chermise | D15: Estacionamiento - CarWash
A16: 3 | B16: 22 | C16: Christian Jaques - Croissant y Pan | D16: Desayuno
A17: 4 | B17: 67 | C17: Loose Moose Lunch | D17: Almuerzo
A18: 4 | B18: 18 | C18: Yochi | D18: Almuerzo
... A64: 25 | B64: 21 | C64: Linkt Peajes | D64: Peajes
A65: 27 | B65: 33 | C65: Cursor Suscription | D65: Otros Personales | E65: =if(and(F65,G65),1,2) -> 2 | F65: =ISBLANK(D65) -> FALSE | G65: =ISNUMBER(B65) -> TRUE
A66: 28 | B66: 80 | C66: Carga Golinkt | D66: Tren - GoCard - Scooter Pega | E66: =if(and(F66,G66),1,2) -> 2 | F66: =ISBLANK(D66) -> FALSE | G66: =ISNUMBER(B66) -> TRUE
A67: 28 | B67: 16 | C67: Burger King - Jueves | D67: Cena | E67: =if(and(F67,G67),1,2) -> 2 | F67: =ISBLANK(D67) -> FALSE | G67: =ISNUMBER(B67) -> TRUE
A68: 28 | B68: 3 | C68: Lime - Jueves | D68: Tren - GoCard - Scooter Pega | E68: =if(and(F68,G68),1,2) -> 2 | F68: =ISBLANK(D68) -> FALSE | G68: =ISNUMBER(B68) -> TRUE
A69: 25 | B69: 31 | C69: Uber eats - Almuerzo Vale | D69: Almuerzo | E69: =if(and(F69,G69),1,2) -> 2 | F69: =ISBLANK(D69) -> FALSE | G69: =ISNUMBER(B69) -> TRUE
A70: 27 | B70: 9 | C70: Christian Jacques - Croissant | D70: Desayuno | E70: =if(and(F70,G70),1,2) -> 2 | F70: =ISBLANK(D70) -> FALSE | G70: =ISNUMBER(B70) -> TRUE
A71: 29 | B71: 34 | C71: Hakataya - Ramen | D71: Almuerzo | E71: =if(and(F71,G71),1,2) -> 2 | F71: =ISBLANK(D71) -> FALSE | G71: =ISNUMBER(B71) -> TRUE
A72: 29 | B72: 14 | C72: Starbucks | D72: Cena | E72: =if(and(F72,G72),1,2) -> 2 | F72: =ISBLANK(D72) -> FALSE | G72: =ISNUMBER(B72) -> TRUE
A73: 29 | B73: 185 | C73: Coles - Pizzas | D73: Super | E73: =if(and(F73,G73),1,2) -> 2 | F73: =ISBLANK(D73) -> FALSE | G73: =ISNUMBER(B73) -> TRUE
A74: 30 | B74: 56 | C74: Corte Pelo | D74: Corte Pelo - Salud - Remedios | E74: =if(and(F74,G74),1,2) -> 2 | F74: =ISBLANK(D74) -> FALSE | G74: =ISNUMBER(B74) -> TRUE
A75: 30 | B75: 7 | C75: OfficeWorks - Print | D75: Otros Personales | E75: =if(and(F75,G75),1,2) -> 2 | F75: =ISBLANK(D75) -> FALSE | G75: =ISNUMBER(B75) -> TRUE
A76: 31 | B76: 22 | C76: Christian Jaques - Pan y Croissant | D76: Desayuno+ | E76: =if(and(F76,G76),1,2) -> 2 | F76: =ISBLANK(D76) -> FALSE | G76: =ISNUMBER(B76) -> TRUE
A77: 31 | B77: 50 | C77: Uber Pega | D77: Uber Pega | E77: =if(and(F77,G77),1,2) -> 2 | F77: =ISBLANK(D77) -> FALSE | G77: =ISNUMBER(B77) -> TRUE
E78: =if(and(F78,G78),1,2) -> 2 | F78: =ISBLANK(D78) -> TRUE | G78: =ISNUMBER(B78) -> FALSE
E79: =if(and(F79,G79),1,2) -> 2 | F79: =ISBLANK(D79) -> TRUE | G79: =ISNUMBER(B79) -> FALSE
E80: =if(and(F80,G80),1,2) -> 2 | F80: =ISBLANK(D80) -> TRUE | G80: =ISNUMBER(B80) -> FALSE
E81: =if(and(F81,G81),1,2) -> 2 | F81: =ISBLANK(D81) -> TRUE | G81: =ISNUMBER(B81) -> FALSE
E82: =if(and(F82,G82),1,2) -> 2 | F82: =ISBLANK(D82) -> TRUE | G82: =ISNUMBER(B82) -> FALSE
E83: =if(and(F83,G83),1,2) -> 2 | F83: =ISBLANK(D83) -> TRUE | G83: =ISNUMBER(B83) -> FALSE
E84: =if(and(F84,G84),1,2) -> 2 | F84: =ISBLANK(D84) -> TRUE | G84: =ISNUMBER(B84) -> FALSE
E85: =if(and(F85,G85),1,2) -> 2 | F85: =ISBLANK(D85) -> TRUE | G85: =ISNUMBER(B85) -> FALSE
...

Sheet Graficos
A1: 31 | R1: Dia
R2: =Acumulado!AJ59 -> 31 | S2: MTD | T2: Rem. Mes | U2: Balance Proyectado
R3: Internet | S3: =Acumulado!AM216 -> -7 | T3: =Acumulado!AN216 -> -7 | U3: -14
R4: Comidas | S4: =Acumulado!AM218 -> 61 | T4: =Acumulado!AN218 -> 61 | U4: 122
R5: Super | S5: =Acumulado!AM221 -> -221 | T5: =Acumulado!AN221 -> -221 | U5: -442
R6: Otros Casa | S6: =Acumulado!AM222 -> 387 | T6: =Acumulado!AN222 -> 387 | U6: 774
R7: Corte Pelo | S7: =Acumulado!AM223 -> -12 | T7: =Acumulado!AN223 -> -12 | U7: -24
R8: Transporte BNE | S8: =Acumulado!AM225 -> 150 | T8: =Acumulado!AN225 -> 150 | U8: 300
R9: Auto | S9: =Acumulado!AM227 -> 145 | T9: =Acumulado!AN227 -> 145 | U9: 290
R10: Gastos Pega | S10: =Acumulado!AM233 -> 164.8 | T10: =Acumulado!AN233 -> 164.8 | U10: 329.6
R11: Otros Personales | S11: =Acumulado!AM236 -> -292.67 | T11: =Acumulado!AN236 -> -292.67 | U11: -585.34
S12: =SUM(S3:S11) -> 375.13 | T12: =SUM(T3:T11) -> 375.13 | U12: 750.26
R13: Total % Acum.
R14: =Acumulado!D192 -> 0.8810546
S15: Item
S16: Luz | T16: Mecanico | U16: REGO | V16: Viajes | W16: Otros Fuera Presupuesto | X16: Obs: | Z16: Total Mensual | AA16: Caja Presupuesto | AB16: % | AC16: Balance Caja | AD16: Sin Gasto Unico | AE16: Ingreso Extra | AF16: Obs:
R17: Enero | S17: 450.11 | T17: 0 | U17: 0 | V17: 0 | W17: 0 | Z17: =SUM(S17:W17)*-1 -> -450.11 | AA17: -136.8 | AB17: 1.0433762 | AC17: -586.91 | AD17: -586.91
R18: Febrero | S18: 0 | T18: 6943 | U18: 0 | V18: 340 | W18: 0 | X18: Viaje Coolangatta (340) / Reparacion Auto (6943) | Z18: =SUM(S18:W18)*-1 -> -7283 | AA18: -1 | AB18: 1 | AC18: -7284 | AD18: -7284 | AE18: 14000 | AF18: Bono Glencore
R19: Marzo | S19: 0 | T19: 0 | U19: 437 | V19: 0 | W19: 0 | X19: REGO Mazda 6 months | Z19: =SUM(S19:W19)*-1 -> -437 | AA19: 893 | AB19: 0.72 | AC19: 456 | AD19: 456
R20: Abril | S20: 487 | T20: 0 | U20: 0 | V20: 0 | W20: 1466 | X20: Luz 3 Meses / Celular S24 Pato (723) / BVB (743) | Z20: =SUM(S20:W20)*-1 -> -1953 | AA20: 496.99452 | AB20: 0.8371612 | AC20: -1456.0055 | AD20: -1456.0055
R21: Mayo | S21: =SUMIF(Data!$D$2:$D$100,S$16,Data!$B$2:$B$100) -> 0 | T21: =SUMIF(Data!$D$2:$D$100,T$16,Data!$B$2:$B$100) -> 0 | U21: =SUMIF(Data!$D$2:$D$100,U$16,Data!$B$2:$B$100) -> 0 | V21: =SUMIF(Data!$D$2:$D$100,V$16,Data!$B$2:$B$100) -> 0 | W21: =SUMIF(Data!$D$2:$D$100,W$16,Data!$B$2:$B$100) -> 660 | X21: Fragomen Reu (660) | Z21: =SUM(S21:W21)*-1 -> -660 | AA21: =$S$12 -> 375.13 | AB21: =Acumulado!$D$192 -> 0.8810546 | AC21: -284.87 | AD21: -284.87
R22: Junio | S22: 412.5 | Z22: =SUM(S22:W22)*-1 -> -412.5 | AC22: -412.5 | AD22: -412.5
R23: Julio | Z23: =SUM(S23:W23)*-1 -> 0 | AC23: 0 | AD23: 0
R24: Agosto | Z24: =SUM(S24:W24)*-1 -> 0 | AC24: 0 | AD24: 0
R25: Septiembre | S25: 412.5 | Z25: =SUM(S25:W25)*-1 -> -412.5 | AC25: -412.5 | AD25: -412.5
R26: Octubre | T26: 600 | U26: 450 | Z26: =SUM(S26:W26)*-1 -> -1050 | AC26: -1050 | AD26: -1050
R27: Noviembre | Z27: =SUM(S27:W27)*-1 -> 0 | AC27: 0 | AD27: 0
R28: Diciembre | S28: 412.5 | V28: 3000 | Z28: =SUM(S28:W28)*-1 -> -3412.5 | AC28: -3412.5 | AD28: -3412.5
R29: Gasto Año | S29: =SUM(S17:S28) -> 2174.61 | T29: =SUM(T17:T28) -> 7543 | U29: =SUM(U17:U28) -> 887 | V29: =SUM(V17:V28) -> 3340 | W29: =SUM(W17:W28) -> 2126 | Z29: =SUM(S29:W29) -> 16070.61 | AA29: =SUM(AA17:AA28) -> 1627.3245 | AB29: =AVERAGE(AB17:AB28) -> 0.89631841 | AC29: -14443.285 | AD29: -14443.285 | AE29: 14000 | AF29: 0
R30: Presupuesto | S30: =Presupuesto!F7/4*3 -> 1649.7 | T30: =Presupuesto!F39 -> 600 | U30: =Presupuesto!F40 -> 900 | V30: =Presupuesto!F54 -> 3000 | W30: 0 | Z30: =SUM(S30:W30) -> 6149.7
R31: Diferencia | S31: =S30-S29 -> -524.91 | T31: =T30-T29 -> -6943 | U31: =U30-U29 -> 13 | V31: =V30-V29 -> -340 | W31: =W30-W29 -> -2126 | Z31: =SUM(S31:W31) -> -9920.91 | AA31: -8293.5855
R32: Diff x Mes | S32: =S31/12 -> -43.7425 | T32: =T31/12 -> -578.58333 | U32: =U31/12 -> 1.0833333 | V32: =V31/12 -> -28.333333 | W32: =W31/12 -> -177.16667 | Z32: =SUM(S32:W32) -> -826.7425 | AA32: =AA31/12 -> -691.13212
AA34: Balance vs Budget | AB34: vs BP sin extras
Z35: Anual | AA35: =Z31+AA29+AE29 -> 5706.4145 | AB35: =AA35-W31 -> 7832.4145
Z36: Mensual | AA36: =AA35/12 -> 475.53454 | AB36: =AB35/12 -> 652.70121
R38: Otros Fuera Presupuesto
R39: Motivo | S39: Item | T39: Monto | U39: Status | V39: Obs.
S40: Total | T40: =SUM(T41:T55) -> 8937
R41: Viaje Ricardo-Paty | S41: Vuelos SLC-BNE | T41: 3675 | U41: Pagado | W41: =IF(U41="Pagado",1,IF(U41="Solo Cotizado",2,IF(U41="Reservado no Pagado",3,4))) -> 1
R42: Viaje Ricardo-Paty | S42: Hotel Hobart | T42: 996 | U42: Pagado | W42: =IF(U42="Pagado",1,IF(U42="Solo Cotizado",2,IF(U42="Reservado no Pagado",3,4))) -> 1
...

Sheet Presupuesto
C2: Weeks/Year | D2: 52 | F2: CLP/AUD | G2: 600
C3: Weeks/Month | D3: 4.3
A5: Costos Fijos | D5: Week | E5: Month | F5: Year | H5: Dias Mes | I5: Clasificacion | J5: SubClasificacion | K5: Presupuesto Mensual | L5: Dia
C6: Depto | D6: 725 | E6: =D6*$D$3 -> 3117.5 | F6: =E6*12 -> 37410 | H6: =Graficos!A1 -> 31 | I6: Costo Fijo - Depto | J6: Depto | K6: =E6 -> 3117.5 | L6: =K6/$H$6 -> 100.56452 | N6: Mensual
C7: Luz | D7: =E7/$D$3 -> 42.627907 | E7: 183.3 | F7: =E7*12 -> 2199.6 | I7: Costo Fijo - Depto | J7: Luz | K7: =E7 -> 183.3 | L7: =K7/$H$6 -> 5.9129032 | N7: Trimestral
C8: Internet | D8: =E8/$D$3 -> 20.465116 | E8: 88 | F8: =E8*12 -> 1056 | I8: Costo Fijo - Depto | J8: Internet | K8: =E8 -> 88 | L8: =K8/$H$6 -> 2.8387097 | N8: Mensual
I9: Costo Fijo - Otros | J9: Bupa | K9: =E12 -> 230 | L9: =K9/$H$6 -> 7.4193548 | N9: Mensual
B10: SubTotal | C10: Depto | D10: =SUM(D6:D9) -> 788.09302 | E10: =SUM(E6:E9) -> 3388.8 | F10: =SUM(F6:F9) -> 40665.6 | I10: Costo Fijo - Otros | J10: Telstra | K10: =E13 -> 140 | L10: =K10/$H$6 -> 4.516129 | N10: Mensual
I11: Costo Variable - Comidas | J11: Desayuno | K11: =E20 -> 129 | L11: =K11/$H$6 -> 4.1612903 | M11: =SUMIFS(Data!$B$2:$B$80,Data!$D$2:$D$80,$J$6:$J$32) -> 156 | N11: Mensual
C12: Bupa | D12: =E12/$D$3 -> 53.488372 | E12: 230 | F12: =E12*12 -> 2760 | I12: Costo Variable - Comidas | J12: Almuerzo | K12: =E21 -> 344 | L12: =K12/$H$6 -> 11.096774 | M12: =SUMIFS(Data!$B$2:$B$80,Data!$D$2:$D$80,$J$6:$J$32) -> 281 | N12: Mensual
C13: Telstra | D13: =E13/$D$3 -> 32.55814 | E13: 140 | F13: =E13*12 -> 1680 | I13: Costo Variable - Comidas | J13: Cena | K13: =E22 -> 215 | L13: =K13/$H$6 -> 6.9354839 | M13: =SUMIFS(Data!$B$2:$B$80,Data!$D$2:$D$80,$J$6:$J$32) -> 190 | N13: Mensual
I14: Costo Variable - Comidas | J14: Super | K14: =E26 -> 645 | L14: =K14/$H$6 -> 20.806452 | M14: =SUMIFS(Data!$B$2:$B$80,Data!$D$2:$D$80,$J$6:$J$32) -> 866 | N14: Mensual
B15: SubTotal | C15: Costos Fijos | D15: =SUM(D12:D14) -> 86.046512 | E15: =SUM(E12:E14) -> 370 | F15: =SUM(F12:F14) -> 4440 | I15: Costo Variable - Otros | J15: Otros Casa | K15: =E25 -> 215 | L15: =K15/$H$6 -> 6.9354839 | M15: =SUMIFS(Data!$B$2:$B$80,Data!$D$2:$D$80,$J$6:$J$32) -> 0 | N15: Mensual
I16: Costo Variable - Otros | J16: Corte Pelo - Salud - Remedios | K16: =E29 -> 100 | L16: =K16/$H$6 -> 3.2258065 | M16: =SUMIFS(Data!$B$2:$B$80,Data!$D$2:$D$80,$J$6:$J$32) -> 112 | N16: Mensual
B17: SubTotal Fijos | C17: Costos Fijos | D17: =D15+D10 -> 874.13953 | E17: =E15+E10 -> 3758.8 | F17: =F15+F10 -> 45105.6 | I17: Costo Variable - Otros | J17: Otros | K17: =E24 -> 172 | L17: =K17/$H$6 -> 5.5483871 | M17: =SUMIFS(Data!$B$2:$B$80,Data!$D$2:$D$80,$J$6:$J$32) -> 0 | N17: Mensual
A18: Costos Variables | I18: Costo Variable - Transporte | J18: Transporte - Scooter | K18: =E30 -> 50 | L18: =K18/$H$6 -> 1.6129032 | M18: =SUMIFS(Data!$B$2:$B$80,Data!$D$2:$D$80,$J$6:$J$32) -> 20 | N18: Mensual
I19: Costo Variable - Transporte | J19: Uber | K19: =E31 -> 120 | L19: =K19/$H$6 -> 3.8709677 | M19: =SUMIFS(Data!$B$2:$B$80,Data!$D$2:$D$80,$J$6:$J$32) -> 0 | N19: Mensual
B20: Comidas | C20: Desayuno | D20: 30 | E20: =D20*$D$3 -> 129 | F20: =E20*12 -> 1548 | I20: Costo Variable - Auto | J20: Bencina | K20: =E36 -> 80 | L20: =K20/$H$6 -> 2.5806452 | M20: =SUMIFS(Data!$B$2:$B$80,Data!$D$2:$D$80,$J$6:$J$32) -> 46 | N20: Mensual
C21: Almuerzo | D21: 80 | E21: =D21*$D$3 -> 344 | F21: =E21*12 -> 4128 | I21: Costo Variable - Auto | J21: Seguro | K21: =E37 -> 100 | L21: =K21/$H$6 -> 3.2258065 | M21: =SUMIFS(Data!$B$2:$B$80,Data!$D$2:$D$80,$J$6:$J$32) -> 0 | N21: Mensual
C22: Cena | D22: 50 | E22: =D22*$D$3 -> 215 | F22: =E22*12 -> 2580 | I22: Costo Variable - Auto | J22: Estacionamiento - CarWash | K22: =E38 -> 35 | L22: =K22/$H$6 -> 1.1290323 | M22: =SUMIFS(Data!$B$2:$B$80,Data!$D$2:$D$80,$J$6:$J$32) -> 22 | N22: Mensual
I23: Costo Variable - Auto | J23: Mecanico | K23: =E39 -> 50 | L23: =K23/$H$6 -> 1.6129032 | M23: =SUMIFS(Data!$B$2:$B$80,Data!$D$2:$D$80,$J$6:$J$32) -> 0 | N23: Anual
C24: Otros | D24: 40 | E24: =D24*$D$3 -> 172 | F24: =E24*12 -> 2064 | I24: Costo Variable - Auto | J24: REGO | K24: =E40 -> 75 | L24: =K24/$H$6 -> 2.4193548 | M24: =SUMIFS(Data!$B$2:$B$80,Data!$D$2:$D$80,$J$6:$J$32) -> 0 | N24: Semestral
C25: Otros Casa | D25: 50 | E25: =D25*$D$3 -> 215 | F25: =E25*12 -> 2580 | I25: Costo Variable - Auto | J25: Peajes | K25: =E41 -> 40 | L25: =K25/$H$6 -> 1.2903226 | M25: =SUMIFS(Data!$B$2:$B$80,Data!$D$2:$D$80,$J$6:$J$32) -> 42 | N25: Mensual
C26: Super | D26: 150 | E26: =D26*$D$3 -> 645 | F26: =E26*12 -> 7740 | I26: Costo Variable - Gasto Pega | J26: Uber Pega | K26: =E44 -> 236.5 | L26: =K26/$H$6 -> 7.6290323 | M26: =SUMIFS(Data!$B$2:$B$80,Data!$D$2:$D$80,$J$6:$J$32) -> 202 | N26: Mensual
B27: SubTotal | C27: Comida + Super | D27: =SUM(D20:D26) -> 400 | E27: =SUM(E20:E26) -> 1720 | F27: =SUM(F20:F26) -> 20640 | I27: Costo Variable - Gasto Pega | J27: Tren - GoCard - Scooter Pega | K27: =E45 -> 98.9 | L27: =K27/$H$6 -> 3.1903226 | M27: =SUMIFS(Data!$B$2:$B$80,Data!$D$2:$D$80,$J$6:$J$32) -> 89 | N27: Mensual
I28: Costo Variable - Gasto Pega | J28: Parking - Otros Pega | K28: =E46 -> 120.4 | L28: =K28/$H$6 -> 3.883871 | M28: =SUMIFS(Data!$B$2:$B$80,Data!$D$2:$D$80,$J$6:$J$32) -> 0 | N28: Mensual
C29: Corte Pelo | D29: =E29/$D$3 -> 23.255814 | E29: 100 | F29: =E29*12 -> 1200 | I29: Costo Variable - Personales | J29: Otros Personales | K29: =E50 -> 150 | L29: =K29/$H$6 -> 4.8387097 | M29: =SUMIFS(Data!$B$2:$B$80,Data!$D$2:$D$80,$J$6:$J$32) -> 388.67 | N29: Mensual
C30: Transporte | D30: =E30/$D$3 -> 11.627907 | E30: 50 | F30: =E30*12 -> 600 | I30: Costo Variable - Personales | J30: Libros - Cursos | K30: =E51 -> 129 | L30: =K30/$H$6 -> 4.1612903 | M30: =SUMIFS(Data!$B$2:$B$80,Data!$D$2:$D$80,$J$6:$J$32) -> 0 | N30: Mensual
C31: Uber | D31: =E31/$D$3 -> 27.906977 | E31: 120 | F31: =E31*12 -> 1440 | I31: Costo Variable - Personales | J31: Ropa - Accesorios | K31: =E52 -> 86 | L31: =K31/$H$6 -> 2.7741935 | M31: =SUMIFS(Data!$B$2:$B$80,Data!$D$2:$D$80,$J$6:$J$32) -> 178 | N31: Mensual
I32: Costo Variable - Personales | J32: Regalos - Eventos | K32: =E53 | L32: =K32/$H$6 -> 0 | M32: =SUMIFS(Data!$B$2:$B$80,Data!$D$2:$D$80,$J$6:$J$32) -> 91 | N32: Mensual
I33: Costo Variable - Personales | J33: Viajes | K33: =E54 -> 250 | L33: =K33/$H$6 -> 8.0645161 | M33: =SUMIFS(Data!$B$2:$B$80,Data!$D$2:$D$80,$J$6:$J$32) -> 0 | N33: Anual
B34: SubTotal | C34: Otros | D34: =sum(D29:D33) -> 62.790698 | E34: =sum(E29:E33) -> 270 | F34: =sum(F29:F33) -> 3240 | J34: Otros Fuera Presupuesto
C36: Bencina | D36: =E36/$D$3 -> 18.604651 | E36: 80 | F36: =E36*12 -> 960 | I36: Presupuesto Total x Mes | K36: =SUM(K6:K33) -> 7199.6
C37: Seguro Auto | D37: =E37/$D$3 -> 23.255814 | E37: 100 | F37: =E37*12 -> 1200 | I37: Presupuesto - Variable | K37: =SUM(K25:K31,K11:K22,K8) -> 3153.8
C38: Estacionamiento | D38: =E38/$D$3 -> 8.1395349 | E38: 35 | F38: =E38*12 -> 420
C39: Mecanico | D39: =E39/$D$3 -> 11.627907 | E39: =F39/12 -> 50 | F39: 600
C40: REGO | D40: =E40/$D$3 -> 17.44186 | E40: =F40/12 -> 75 | F40: 900
C41: Peajes/Linkt | D41: =E41/$D$3 -> 9.3023256 | E41: 40 | F41: =E41*12 -> 480
B42: SubTotal | C42: Auto | D42: =sum(D36:D41) -> 88.372093 | E42: =sum(E36:E41) -> 380 | F42: =sum(F36:F41) -> 4560
B44: Trabajo | C44: Uber a Pega | D44: 55 | E44: =D44*$D$3 -> 236.5 | F44: =E44*12 -> 2838
...

Sheet Acumulado
C2: Dia | D2: 1 | E2: =D2+1 -> 2 | F2: =E2+1 -> 3 | G2: =F2+1 -> 4 | H2: =G2+1 -> 5 | I2: =H2+1 -> 6 | J2: =I2+1 -> 7 | K2: =J2+1 -> 8 | L2: =K2+1 -> 9 | ... AH2: =AG2+1 -> 31 | AI2: Total Mes
A3: Real | B3: Clasificacion | C3: SubClasificacion
B4: Costo Fijo - Depto | C4: Luz | D4: =SUMIFS(Data!$B$2:$B$100,Data!$A$2:$A$100,D$2,Data!$D$2:$D$100,$C4) -> 0 | E4: =SUMIFS(Data!$B$2:$B$100,Data!$A$2:$A$100,E$2,Data!$D$2:$D$100,$C4) -> 0 | F4: =SUMIFS(Data!$B$2:$B$100,Data!$A$2:$A$100,F$2,Data!$D$2:$D$100,$C4) -> 0 | G4: =SUMIFS(Data!$B$2:$B$100,Data!$A$2:$A$100,G$2,Data!$D$2:$D$100,$C4) -> 0 | H4: =SUMIFS(Data!$B$2:$B$100,Data!$A$2:$A$100,H$2,Data!$D$2:$D$100,$C4) -> 0 | I4: =SUMIFS(Data!$B$2:$B$100,Data!$A$2:$A$100,I$2,Data!$D$2:$D$100,$C4) -> 0 | J4: =SUMIFS(Data!$B$2:$B$100,Data!$A$2:$A$100,J$2,Data!$D$2:$D$100,$C4) -> 0 | K4: =SUMIFS(Data!$B$2:$B$100,Data!$A$2:$A$100,K$2,Data!$D$2:$D$100,$C4) -> 0 | ... AH4: =SUMIFS(Data!$B$2:$B$100,Data!$A$2:$A$100,AH$2,Data!$D$2:$D$100,$C4) -> 0 | AI4: =SUM(D4:AH4) -> 0
B5: Costo Fijo - Depto | C5: Internet | D5: =SUMIFS(Data!$B$2:$B$100,Data!$A$2:$A$100,D$2,Data!$D$2:$D$100,$C5) -> 95 | E5: =SUMIFS(Data!$B$2:$B$100,Data!$A$2:$A$100,E$2,Data!$D$2:$D$100,$C5) -> 0 | F5: =SUMIFS(Data!$B$2:$B$100,Data!$A$2:$A$100,F$2,Data!$D$2:$D$100,$C5) -> 0 | G5: =SUMIFS(Data!$B$2:$B$100,Data!$A$2:$A$100,G$2,Data!$D$2:$D$100,$C5) -> 0 | H5: =SUMIFS(Data!$B$2:$B$100,Data!$A$2:$A$100,H$2,Data!$D$2:$D$100,$C5) -> 0 | I5: =SUMIFS(Data!$B$2:$B$100,Data!$A$2:$A$100,I$2,Data!$D$2:$D$100,$C5) -> 0 | J5: =SUMIFS(Data!$B$2:$B$100,Data!$A$2:$A$100,J$2,Data!$D$2:$D$100,$C5) -> 0 | K5: =SUMIFS(Data!$B$2:$B$100,Data!$A$2:$A$100,K$2,Data!$D$2:$D$100,$C5) -> 0 | ... AH5: =SUMIFS(Data!$B$2:$B$100,Data!$A$2:$A$100,AH$2,Data!$D$2:$D$100,$C5) -> 0 | AI5: =SUM(D5:AH5) -> 95
B6: Costo Variable - Comidas | C6: Desayuno | D6: =SUMIFS(Data!$B$2:$B$100,Data!$A$2:$A$100,D$2,Data!$D$2:$D$100,$C6) -> 11 | E6: =SUMIFS(Data!$B$2:$B$100,Data!$A$2:$A$100,E$2,Data!$D$2:$D$100,$C6) -> 0 | F6: =SUMIFS(Data!$B$2:$B$100,Data!$A$2:$A$100,F$2,Data!$D$2:$D$100,$C6) -> 22 | G6: =SUMIFS(Data!$B$2:$B$100,Data!$A$2:$A$100,G$2,Data!$D$2:$D$100,$C6) -> 0 | H6: =SUMIFS(Data!$B$2:$B$100,Data!$A$2:$A$100,H$2,Data!$D$2:$D$100,$C6) -> 0 | I6: =SUMIFS(Data!$B$2:$B$100,Data!$A$2:$A$100,I$2,Data!$D$2:$D$100,$C6) -> 0 | J6: =SUMIFS(Data!$B$2:$B$100,Data!$A$2:$A$100,J$2,Data!$D$2:$D$100,$C6) -> 0 | K6: =SUMIFS(Data!$B$2:$B$100,Data!$A$2:$A$100,K$2,Data!$D$2:$D$100,$C6) -> 0 | ... AH6: =SUMIFS(Data!$B$2:$B$100,Data!$A$2:$A$100,AH$2,Data!$D$2:$D$100,$C6) -> 0 | AI6: =SUM(D6:AH6) -> 156
B7: Costo Variable - Comidas | C7: Almuerzo | D7: =SUMIFS(Data!$B$2:$B$100,Data!$A$2:$A$100,D$2,Data!$D$2:$D$100,$C7) -> 0 | E7: =SUMIFS(Data!$B$2:$B$100,Data!$A$2:$A$100,E$2,Data!$D$2:$D$100,$C7) -> 39 | F7: =SUMIFS(Data!$B$2:$B$100,Data!$A$2:$A$100,F$2,Data!$D$2:$D$100,$C7) -> 0 | G7: =SUMIFS(Data!$B$2:$B$100,Data!$A$2:$A$100,G$2,Data!$D$2:$D$100,$C7) -> 85 | H7: =SUMIFS(Data!$B$2:$B$100,Data!$A$2:$A$100,H$2,Data!$D$2:$D$100,$C7) -> 0 | I7: =SUMIFS(Data!$B$2:$B$100,Data!$A$2:$A$100,I$2,Data!$D$2:$D$100,$C7) -> 0 | J7: =SUMIFS(Data!$B$2:$B$100,Data!$A$2:$A$100,J$2,Data!$D$2:$D$100,$C7) -> 0 | K7: =SUMIFS(Data!$B$2:$B$100,Data!$A$2:$A$100,K$2,Data!$D$2:$D$100,$C7) -> 0 | ... AH7: =SUMIFS(Data!$B$2:$B$100,Data!$A$2:$A$100,AH$2,Data!$D$2:$D$100,$C7) -> 0 | AI7: =SUM(D7:AH7) -> 281
B8: Costo Variable - Comidas | C8: Cena | D8: =SUMIFS(Data!$B$2:$B$100,Data!$A$2:$A$100,D$2,Data!$D$2:$D$100,$C8) -> 0 | E8: =SUMIFS(Data!$B$2:$B$100,Data!$A$2:$A$100,E$2,Data!$D$2:$D$100,$C8) -> 0 | F8: =SUMIFS(Data!$B$2:$B$100,Data!$A$2:$A$100,F$2,Data!$D$2:$D$100,$C8) -> 0 | G8: =SUMIFS(Data!$B$2:$B$100,Data!$A$2:$A$100,G$2,Data!$D$2:$D$100,$C8) -> 0 | H8: =SUMIFS(Data!$B$2:$B$100,Data!$A$2:$A$100,H$2,Data!$D$2:$D$100,$C8) -> 24 | I8: =SUMIFS(Data!$B$2:$B$100,Data!$A$2:$A$100,I$2,Data!$D$2:$D$100,$C8) -> 0 | J8: =SUMIFS(Data!$B$2:$B$100,Data!$A$2:$A$100,J$2,Data!$D$2:$D$100,$C8) -> 16 | K8: =SUMIFS(Data!$B$2:$B$100,Data!$A$2:$A$100,K$2,Data!$D$2:$D$100,$C8) -> 0 | ... AH8: =SUMIFS(Data!$B$2:$B$100,Data!$A$2:$A$100,AH$2,Data!$D$2:$D$100,$C8) -> 0 | AI8: =SUM(D8:AH8) -> 190
B9: Costo Variable - Comidas | C9: Super | D9: =SUMIFS(Data!$B$2:$B$100,Data!$A$2:$A$100,D$2,Data!$D$2:$D$100,$C9) -> 0 | E9: =SUMIFS(Data!$B$2:$B$100,Data!$A$2:$A$100,E$2,Data!$D$2:$D$100,$C9) -> 110 | F9: =SUMIFS(Data!$B$2:$B$100,Data!$A$2:$A$100,F$2,Data!$D$2:$D$100,$C9) -> 0 | G9: =SUMIFS(Data!$B$2:$B$100,Data!$A$2:$A$100,G$2,Data!$D$2:$D$100,$C9) -> 0 | H9: =SUMIFS(Data!$B$2:$B$100,Data!$A$2:$A$100,H$2,Data!$D$2:$D$100,$C9) -> 0 | I9: =SUMIFS(Data!$B$2:$B$100,Data!$A$2:$A$100,I$2,Data!$D$2:$D$100,$C9) -> 0 | J9: =SUMIFS(Data!$B$2:$B$100,Data!$A$2:$A$100,J$2,Data!$D$2:$D$100,$C9) -> 0 | K9: =SUMIFS(Data!$B$2:$B$100,Data!$A$2:$A$100,K$2,Data!$D$2:$D$100,$C9) -> 10 | ... AH9: =SUMIFS(Data!$B$2:$B$100,Data!$A$2:$A$100,AH$2,Data!$D$2:$D$100,$C9) -> 0 | AI9: =SUM(D9:AH9) -> 866
B10: Costo Variable - Otros | C10: Otros Casa | D10: =SUMIFS(Data!$B$2:$B$100,Data!$A$2:$A$100,D$2,Data!$D$2:$D$100,$C10) -> 0 | E10: =SUMIFS(Data!$B$2:$B$100,Data!$A$2:$A$100,E$2,Data!$D$2:$D$100,$C10) -> 0 | F10: =SUMIFS(Data!$B$2:$B$100,Data!$A$2:$A$100,F$2,Data!$D$2:$D$100,$C10) -> 0 | G10: =SUMIFS(Data!$B$2:$B$100,Data!$A$2:$A$100,G$2,Data!$D$2:$D$100,$C10) -> 0 | H10: =SUMIFS(Data!$B$2:$B$100,Data!$A$2:$A$100,H$2,Data!$D$2:$D$100,$C10) -> 0 | I10: =SUMIFS(Data!$B$2:$B$100,Data!$A$2:$A$100,I$2,Data!$D$2:$D$100,$C10) -> 0 | J10: =SUMIFS(Data!$B$2:$B$100,Data!$A$2:$A$100,J$2,Data!$D$2:$D$100,$C10) -> 0 | K10: =SUMIFS(Data!$B$2:$B$100,Data!$A$2:$A$100,K$2,Data!$D$2:$D$100,$C10) -> 0 | ... AH10: =SUMIFS(Data!$B$2:$B$100,Data!$A$2:$A$100,AH$2,Data!$D$2:$D$100,$C10) -> 0 | AI10: =SUM(D10:AH10) -> 0
B11: Costo Variable - Otros | C11: Corte Pelo - Salud - Remedios | D11: =SUMIFS(Data!$B$2:$B$100,Data!$A$2:$A$100,D$2,Data!$D$2:$D$100,$C11) -> 0 | E11: =SUMIFS(Data!$B$2:$B$100,Data!$A$2:$A$100,E$2,Data!$D$2:$D$100,$C11) -> 0 | F11: =SUMIFS(Data!$B$2:$B$100,Data!$A$2:$A$100,F$2,Data!$D$2:$D$100,$C11) -> 0 | G11: =SUMIFS(Data!$B$2:$B$100,Data!$A$2:$A$100,G$2,Data!$D$2:$D$100,$C11) -> 0 | H11: =SUMIFS(Data!$B$2:$B$100,Data!$A$2:$A$100,H$2,Data!$D$2:$D$100,$C11) -> 0 | I11: =SUMIFS(Data!$B$2:$B$100,Data!$A$2:$A$100,I$2,Data!$D$2:$D$100,$C11) -> 0 | J11: =SUMIFS(Data!$B$2:$B$100,Data!$A$2:$A$100,J$2,Data!$D$2:$D$100,$C11) -> 0 | K11: =SUMIFS(Data!$B$2:$B$100,Data!$A$2:$A$100,K$2,Data!$D$2:$D$100,$C11) -> 56 | ... AH11: =SUMIFS(Data!$B$2:$B$100,Data!$A$2:$A$100,AH$2,Data!$D$2:$D$100,$C11) -> 0 | AI11: =SUM(D11:AH11) -> 112
B12: Costo Variable - Otros | C12: Otros | D12: =SUMIFS(Data!$B$2:$B$100,Data!$A$2:$A$100,D$2,Data!$D$2:$D$100,$C12) -> 0 | E12: =SUMIFS(Data!$B$2:$B$100,Data!$A$2:$A$100,E$2,Data!$D$2:$D$100,$C12) -> 0 | F12: =SUMIFS(Data!$B$2:$B$100,Data!$A$2:$A$100,F$2,Data!$D$2:$D$100,$C12) -> 0 | G12: =SUMIFS(Data!$B$2:$B$100,Data!$A$2:$A$100,G$2,Data!$D$2:$D$100,$C12) -> 0 | H12: =SUMIFS(Data!$B$2:$B$100,Data!$A$2:$A$100,H$2,Data!$D$2:$D$100,$C12) -> 0 | I12: =SUMIFS(Data!$B$2:$B$100,Data!$A$2:$A$100,I$2,Data!$D$2:$D$100,$C12) -> 0 | J12: =SUMIFS(Data!$B$2:$B$100,Data!$A$2:$A$100,J$2,Data!$D$2:$D$100,$C12) -> 0 | K12: =SUMIFS(Data!$B$2:$B$100,Data!$A$2:$A$100,K$2,Data!$D$2:$D$100,$C12) -> 0 | ... AH12: =SUMIFS(Data!$B$2:$B$100,Data!$A$2:$A$100,AH$2,Data!$D$2:$D$100,$C12) -> 0 | AI12: =SUM(D12:AH12) -> 0
B13: Costo Variable - Transporte | C13: Transporte - Scooter | D13: =SUMIFS(Data!$B$2:$B$100,Data!$A$2:$A$100,D$2,Data!$D$2:$D$100,$C13) -> 0 | E13: =SUMIFS(Data!$B$2:$B$100,Data!$A$2:$A$100,E$2,Data!$D$2:$D$100,$C13) -> 0 | F13: =SUMIFS(Data!$B$2:$B$100,Data!$A$2:$A$100,F$2,Data!$D$2:$D$100,$C13) -> 0 | G13: =SUMIFS(Data!$B$2:$B$100,Data!$A$2:$A$100,G$2,Data!$D$2:$D$100,$C13) -> 0 | H13: =SUMIFS(Data!$B$2:$B$100,Data!$A$2:$A$100,H$2,Data!$D$2:$D$100,$C13) -> 0 | I13: =SUMIFS(Data!$B$2:$B$100,Data!$A$2:$A$100,I$2,Data!$D$2:$D$100,$C13) -> 0 | J13: =SUMIFS(Data!$B$2:$B$100,Data!$A$2:$A$100,J$2,Data!$D$2:$D$100,$C13) -> 3 | K13: =SUMIFS(Data!$B$2:$B$100,Data!$A$2:$A$100,K$2,Data!$D$2:$D$100,$C13) -> 6 | ... AH13: =SUMIFS(Data!$B$2:$B$100,Data!$A$2:$A$100,AH$2,Data!$D$2:$D$100,$C13) -> 0 | AI13: =SUM(D13:AH13) -> 20
B14: Costo Variable - Transporte | C14: Uber | D14: =SUMIFS(Data!$B$2:$B$100,Data!$A$2:$A$100,D$2,Data!$D$2:$D$100,$C14) -> 0 | E14: =SUMIFS(Data!$B$2:$B$100,Data!$A$2:$A$100,E$2,Data!$D$2:$D$100,$C14) -> 0 | F14: =SUMIFS(Data!$B$2:$B$100,Data!$A$2:$A$100,F$2,Data!$D$2:$D$100,$C14) -> 0 | G14: =SUMIFS(Data!$B$2:$B$100,Data!$A$2:$A$100,G$2,Data!$D$2:$D$100,$C14) -> 0 | H14: =SUMIFS(Data!$B$2:$B$100,Data!$A$2:$A$100,H$2,Data!$D$2:$D$100,$C14) -> 0 | I14: =SUMIFS(Data!$B$2:$B$100,Data!$A$2:$A$100,I$2,Data!$D$2:$D$100,$C14) -> 0 | J14: =SUMIFS(Data!$B$2:$B$100,Data!$A$2:$A$100,J$2,Data!$D$2:$D$100,$C14) -> 0 | K14: =SUMIFS(Data!$B$2:$B$100,Data!$A$2:$A$100,K$2,Data!$D$2:$D$100,$C14) -> 0 | ... AH14: =SUMIFS(Data!$B$2:$B$100,Data!$A$2:$A$100,AH$2,Data!$D$2:$D$100,$C14) -> 0 | AI14: =SUM(D14:AH14) -> 0
B15: Costo Variable - Auto | C15: Bencina | D15: =SUMIFS(Data!$B$2:$B$100,Data!$A$2:$A$100,D$2,Data!$D$2:$D$100,$C15) -> 0 | E15: =SUMIFS(Data!$B$2:$B$100,Data!$A$2:$A$100,E$2,Data!$D$2:$D$100,$C15) -> 0 | F15: =SUMIFS(Data!$B$2:$B$100,Data!$A$2:$A$100,F$2,Data!$D$2:$D$100,$C15) -> 0 | G15: =SUMIFS(Data!$B$2:$B$100,Data!$A$2:$A$100,G$2,Data!$D$2:$D$100,$C15) -> 0 | H15: =SUMIFS(Data!$B$2:$B$100,Data!$A$2:$A$100,H$2,Data!$D$2:$D$100,$C15) -> 0 | I15: =SUMIFS(Data!$B$2:$B$100,Data!$A$2:$A$100,I$2,Data!$D$2:$D$100,$C15) -> 0 | J15: =SUMIFS(Data!$B$2:$B$100,Data!$A$2:$A$100,J$2,Data!$D$2:$D$100,$C15) -> 0 | K15: =SUMIFS(Data!$B$2:$B$100,Data!$A$2:$A$100,K$2,Data!$D$2:$D$100,$C15) -> 0 | ... AH15: =SUMIFS(Data!$B$2:$B$100,Data!$A$2:$A$100,AH$2,Data!$D$2:$D$100,$C15) -> 0 | AI15: =SUM(D15:AH15) -> 46
... B27: Costo Variable - Personales | C27: Regalos - Eventos | D27: =SUMIFS(Data!$B$2:$B$100,Data!$A$2:$A$100,D$2,Data!$D$2:$D$100,$C27) -> 0 | E27: =SUMIFS(Data!$B$2:$B$100,Data!$A$2:$A$100,E$2,Data!$D$2:$D$100,$C27) -> 50 | F27: =SUMIFS(Data!$B$2:$B$100,Data!$A$2:$A$100,F$2,Data!$D$2:$D$100,$C27) -> 0 | G27: =SUMIFS(Data!$B$2:$B$100,Data!$A$2:$A$100,G$2,Data!$D$2:$D$100,$C27) -> 0 | H27: =SUMIFS(Data!$B$2:$B$100,Data!$A$2:$A$100,H$2,Data!$D$2:$D$100,$C27) -> 0 | I27: =SUMIFS(Data!$B$2:$B$100,Data!$A$2:$A$100,I$2,Data!$D$2:$D$100,$C27) -> 0 | J27: =SUMIFS(Data!$B$2:$B$100,Data!$A$2:$A$100,J$2,Data!$D$2:$D$100,$C27) -> 0 | K27: =SUMIFS(Data!$B$2:$B$100,Data!$A$2:$A$100,K$2,Data!$D$2:$D$100,$C27) -> 0 | ... AH27: =SUMIFS(Data!$B$2:$B$100,Data!$A$2:$A$100,AH$2,Data!$D$2:$D$100,$C27) -> 0 | AI27: =SUM(D27:AH27) -> 91
C28: Total | D28: =SUM(D4:D27) -> 237 | E28: =SUM(E4:E27) -> 583.67 | F28: =SUM(F4:F27) -> 22 | G28: =SUM(G4:G27) -> 85 | H28: =SUM(H4:H27) -> 24 | I28: =SUM(I4:I27) -> 0 | J28: =SUM(J4:J27) -> 19 | K28: =SUM(K4:K27) -> 72 | ... AI28: =SUM(AI4:AI27) -> 2778.67
C30: Dia | D30: 1 | E30: =D30+1 -> 2 | F30: =E30+1 -> 3 | G30: =F30+1 -> 4 | H30: =G30+1 -> 5 | I30: =H30+1 -> 6 | J30: =I30+1 -> 7 | K30: =J30+1 -> 8 | L30: =K30+1 -> 9 | ... AH30: =AG30+1 -> 31 | AI30: Total Mes
A31: Presupuesto | B31: Clasificacion | C31: SubClasificacion
B32: Costo Fijo - Depto | C32: Luz | D32: =$AI32/Presupuesto!$H$6*D$30*0 -> 0 | E32: =$AI32/Presupuesto!$H$6*E$30*0 -> 0 | F32: =$AI32/Presupuesto!$H$6*F$30*0 -> 0 | G32: =$AI32/Presupuesto!$H$6*G$30*0 -> 0 | H32: =$AI32/Presupuesto!$H$6*H$30*0 -> 0 | I32: =$AI32/Presupuesto!$H$6*I$30*0 -> 0 | J32: =$AI32/Presupuesto!$H$6*J$30*0 -> 0 | K32: =$AI32/Presupuesto!$H$6*K$30*0 -> 0 | ... AH32: =$AI32/Presupuesto!$H$6*AH$30*0 -> 0 | AI32: =Presupuesto!K7*0 -> 0
B33: Costo Fijo - Depto | C33: Internet | D33: =$AI33/Presupuesto!$H$6*D$30 -> 2.8387097 | E33: =$AI33/Presupuesto!$H$6*E$30 -> 5.6774194 | F33: =$AI33/Presupuesto!$H$6*F$30 -> 8.516129 | G33: =$AI33/Presupuesto!$H$6*G$30 -> 11.354839 | H33: =$AI33/Presupuesto!$H$6*H$30 -> 14.193548 | I33: =$AI33/Presupuesto!$H$6*I$30 -> 17.032258 | J33: =$AI33/Presupuesto!$H$6*J$30 -> 19.870968 | K33: =$AI33/Presupuesto!$H$6*K$30 -> 22.709677 | ... AH33: =$AI33/Presupuesto!$H$6*AH$30 -> 88 | AI33: =Presupuesto!K8 -> 88
B34: Costo Variable - Comidas | C34: Desayuno | D34: =$AI34/Presupuesto!$H$6*D$30 -> 4.1612903 | E34: =$AI34/Presupuesto!$H$6*E$30 -> 8.3225806 | F34: =$AI34/Presupuesto!$H$6*F$30 -> 12.483871 | G34: =$AI34/Presupuesto!$H$6*G$30 -> 16.645161 | H34: =$AI34/Presupuesto!$H$6*H$30 -> 20.806452 | I34: =$AI34/Presupuesto!$H$6*I$30 -> 24.967742 | J34: =$AI34/Presupuesto!$H$6*J$30 -> 29.129032 | K34: =$AI34/Presupuesto!$H$6*K$30 -> 33.290323 | ... AH34: =$AI34/Presupuesto!$H$6*AH$30 -> 129 | AI34: =Presupuesto!K11 -> 129
B35: Costo Variable - Comidas | C35: Almuerzo | D35: =$AI35/Presupuesto!$H$6*D$30 -> 11.096774 | E35: =$AI35/Presupuesto!$H$6*E$30 -> 22.193548 | F35: =$AI35/Presupuesto!$H$6*F$30 -> 33.290323 | G35: =$AI35/Presupuesto!$H$6*G$30 -> 44.387097 | H35: =$AI35/Presupuesto!$H$6*H$30 -> 55.483871 | I35: =$AI35/Presupuesto!$H$6*I$30 -> 66.580645 | J35: =$AI35/Presupuesto!$H$6*J$30 -> 77.677419 | K35: =$AI35/Presupuesto!$H$6*K$30 -> 88.774194 | ... AH35: =$AI35/Presupuesto!$H$6*AH$30 -> 344 | AI35: =Presupuesto!K12 -> 344
B36: Costo Variable - Comidas | C36: Cena | D36: =$AI36/Presupuesto!$H$6*D$30 -> 6.9354839 | E36: =$AI36/Presupuesto!$H$6*E$30 -> 13.870968 | F36: =$AI36/Presupuesto!$H$6*F$30 -> 20.806452 | G36: =$AI36/Presupuesto!$H$6*G$30 -> 27.741935 | H36: =$AI36/Presupuesto!$H$6*H$30 -> 34.677419 | I36: =$AI36/Presupuesto!$H$6*I$30 -> 41.612903 | J36: =$AI36/Presupuesto!$H$6*J$30 -> 48.548387 | K36: =$AI36/Presupuesto!$H$6*K$30 -> 55.483871 | ... AH36: =$AI36/Presupuesto!$H$6*AH$30 -> 215 | AI36: =Presupuesto!K13 -> 215
B37: Costo Variable - Comidas | C37: Super | D37: =$AI37/Presupuesto!$H$6*D$30 -> 20.806452 | E37: =$AI37/Presupuesto!$H$6*E$30 -> 41.612903 | F37: =$AI37/Presupuesto!$H$6*F$30 -> 62.419355 | G37: =$AI37/Presupuesto!$H$6*G$30 -> 83.225806 | H37: =$AI37/Presupuesto!$H$6*H$30 -> 104.03226 | I37: =$AI37/Presupuesto!$H$6*I$30 -> 124.83871 | J37: =$AI37/Presupuesto!$H$6*J$30 -> 145.64516 | K37: =$AI37/Presupuesto!$H$6*K$30 -> 166.45161 | ... AH37: =$AI37/Presupuesto!$H$6*AH$30 -> 645 | AI37: =Presupuesto!K14 -> 645
B38: Costo Variable - Otros | C38: Otros Casa | D38: =$AI38/Presupuesto!$H$6*D$30 -> 6.9354839 | E38: =$AI38/Presupuesto!$H$6*E$30 -> 13.870968 | F38: =$AI38/Presupuesto!$H$6*F$30 -> 20.806452 | G38: =$AI38/Presupuesto!$H$6*G$30 -> 27.741935 | H38: =$AI38/Presupuesto!$H$6*H$30 -> 34.677419 | I38: =$AI38/Presupuesto!$H$6*I$30 -> 41.612903 | J38: =$AI38/Presupuesto!$H$6*J$30 -> 48.548387 | K38: =$AI38/Presupuesto!$H$6*K$30 -> 55.483871 | ... AH38: =$AI38/Presupuesto!$H$6*AH$30 -> 215 | AI38: =Presupuesto!K15 -> 215
B39: Costo Variable - Otros | C39: Corte Pelo - Salud - Remedios | D39: =$AI39/Presupuesto!$H$6*D$30 -> 3.2258065 | E39: =$AI39/Presupuesto!$H$6*E$30 -> 6.4516129 | F39: =$AI39/Presupuesto!$H$6*F$30 -> 9.6774194 | G39: =$AI39/Presupuesto!$H$6*G$30 -> 12.903226 | H39: =$AI39/Presupuesto!$H$6*H$30 -> 16.129032 | I39: =$AI39/Presupuesto!$H$6*I$30 -> 19.354839 | J39: =$AI39/Presupuesto!$H$6*J$30 -> 22.580645 | K39: =$AI39/Presupuesto!$H$6*K$30 -> 25.806452 | ... AH39: =$AI39/Presupuesto!$H$6*AH$30 -> 100 | AI39: =Presupuesto!K16 -> 100
B40: Costo Variable - Otros | C40: Otros | D40: =$AI40/Presupuesto!$H$6*D$30 -> 5.5483871 | E40: =$AI40/Presupuesto!$H$6*E$30 -> 11.096774 | F40: =$AI40/Presupuesto!$H$6*F$30 -> 16.645161 | G40: =$AI40/Presupuesto!$H$6*G$30 -> 22.193548 | H40: =$AI40/Presupuesto!$H$6*H$30 -> 27.741935 | I40: =$AI40/Presupuesto!$H$6*I$30 -> 33.290323 | J40: =$AI40/Presupuesto!$H$6*J$30 -> 38.83871 | K40: =$AI40/Presupuesto!$H$6*K$30 -> 44.387097 | ... AH40: =$AI40/Presupuesto!$H$6*AH$30 -> 172 | AI40: =Presupuesto!K17 -> 172
B41: Costo Variable - Transporte | C41: Transporte - Scooter | D41: =$AI41/Presupuesto!$H$6*D$30 -> 1.6129032 | E41: =$AI41/Presupuesto!$H$6*E$30 -> 3.2258065 | F41: =$AI41/Presupuesto!$H$6*F$30 -> 4.8387097 | G41: =$AI41/Presupuesto!$H$6*G$30 -> 6.4516129 | H41: =$AI41/Presupuesto!$H$6*H$30 -> 8.0645161 | I41: =$AI41/Presupuesto!$H$6*I$30 -> 9.6774194 | J41: =$AI41/Presupuesto!$H$6*J$30 -> 11.290323 | K41: =$AI41/Presupuesto!$H$6*K$30 -> 12.903226 | ... AH41: =$AI41/Presupuesto!$H$6*AH$30 -> 50 | AI41: =Presupuesto!K18 -> 50
B42: Costo Variable - Transporte | C42: Uber | D42: =$AI42/Presupuesto!$H$6*D$30 -> 3.8709677 | E42: =$AI42/Presupuesto!$H$6*E$30 -> 7.7419355 | F42: =$AI42/Presupuesto!$H$6*F$30 -> 11.612903 | G42: =$AI42/Presupuesto!$H$6*G$30 -> 15.483871 | H42: =$AI42/Presupuesto!$H$6*H$30 -> 19.354839 | I42: =$AI42/Presupuesto!$H$6*I$30 -> 23.225806 | J42: =$AI42/Presupuesto!$H$6*J$30 -> 27.096774 | K42: =$AI42/Presupuesto!$H$6*K$30 -> 30.967742 | ... AH42: =$AI42/Presupuesto!$H$6*AH$30 -> 120 | AI42: =Presupuesto!K19 -> 120
B43: Costo Variable - Auto | C43: Bencina | D43: =$AI43/Presupuesto!$H$6*D$30 -> 2.5806452 | E43: =$AI43/Presupuesto!$H$6*E$30 -> 5.1612903 | F43: =$AI43/Presupuesto!$H$6*F$30 -> 7.7419355 | G43: =$AI43/Presupuesto!$H$6*G$30 -> 10.322581 | H43: =$AI43/Presupuesto!$H$6*H$30 -> 12.903226 | I43: =$AI43/Presupuesto!$H$6*I$30 -> 15.483871 | J43: =$AI43/Presupuesto!$H$6*J$30 -> 18.064516 | K43: =$AI43/Presupuesto!$H$6*K$30 -> 20.645161 | ... AH43: =$AI43/Presupuesto!$H$6*AH$30 -> 80 | AI43: =Presupuesto!K20 -> 80
B44: Costo Variable - Auto | C44: Seguro | D44: =$AI44/Presupuesto!$H$6*D$30 -> 3.2258065 | E44: =$AI44/Presupuesto!$H$6*E$30 -> 6.4516129 | F44: =$AI44/Presupuesto!$H$6*F$30 -> 9.6774194 | G44: =$AI44/Presupuesto!$H$6*G$30 -> 12.903226 | H44: =$AI44/Presupuesto!$H$6*H$30 -> 16.129032 | I44: =$AI44/Presupuesto!$H$6*I$30 -> 19.354839 | J44: =$AI44/Presupuesto!$H$6*J$30 -> 22.580645 | K44: =$AI44/Presupuesto!$H$6*K$30 -> 25.806452 | ... AH44: =$AI44/Presupuesto!$H$6*AH$30 -> 100 | AI44: =Presupuesto!K21 -> 100
B45: Costo Variable - Auto | C45: Estacionamiento - CarWash | D45: =$AI45/Presupuesto!$H$6*D$30 -> 1.1290323 | E45: =$AI45/Presupuesto!$H$6*E$30 -> 2.2580645 | F45: =$AI45/Presupuesto!$H$6*F$30 -> 3.3870968 | G45: =$AI45/Presupuesto!$H$6*G$30 -> 4.516129 | H45: =$AI45/Presupuesto!$H$6*H$30 -> 5.6451613 | I45: =$AI45/Presupuesto!$H$6*I$30 -> 6.7741935 | J45: =$AI45/Presupuesto!$H$6*J$30 -> 7.9032258 | K45: =$AI45/Presupuesto!$H$6*K$30 -> 9.0322581 | ... AH45: =$AI45/Presupuesto!$H$6*AH$30 -> 35 | AI45: =Presupuesto!K22 -> 35
B46: Costo Variable - Auto | C46: Mecanico | D46: =$AI46/Presupuesto!$H$6*D$30*0 -> 0 | E46: =$AI46/Presupuesto!$H$6*E$30*0 -> 0 | F46: =$AI46/Presupuesto!$H$6*F$30*0 -> 0 | G46: =$AI46/Presupuesto!$H$6*G$30*0 -> 0 | H46: =$AI46/Presupuesto!$H$6*H$30*0 -> 0 | I46: =$AI46/Presupuesto!$H$6*I$30*0 -> 0 | J46: =$AI46/Presupuesto!$H$6*J$30*0 -> 0 | K46: =$AI46/Presupuesto!$H$6*K$30*0 -> 0 | ... AH46: =$AI46/Presupuesto!$H$6*AH$30*0 -> 0 | AI46: =Presupuesto!K23*0 -> 0
B47: Costo Variable - Auto | C47: REGO | D47: =$AI47/Presupuesto!$H$6*D$30*0 -> 0 | E47: =$AI47/Presupuesto!$H$6*E$30*0 -> 0 | F47: =$AI47/Presupuesto!$H$6*F$30*0 -> 0 | G47: =$AI47/Presupuesto!$H$6*G$30*0 -> 0 | H47: =$AI47/Presupuesto!$H$6*H$30*0 -> 0 | I47: =$AI47/Presupuesto!$H$6*I$30*0 -> 0 | J47: =$AI47/Presupuesto!$H$6*J$30*0 -> 0 | K47: =$AI47/Presupuesto!$H$6*K$30*0 -> 0 | ... AH47: =$AI47/Presupuesto!$H$6*AH$30*0 -> 0 | AI47: =Presupuesto!K24*0 -> 0
B48: Costo Variable - Auto | C48: Peajes | D48: =$AI48/Presupuesto!$H$6*D$30 -> 1.2903226 | E48: =$AI48/Presupuesto!$H$6*E$30 -> 2.5806452 | F48: =$AI48/Presupuesto!$H$6*F$30 -> 3.8709677 | G48: =$AI48/Presupuesto!$H$6*G$30 -> 5.1612903 | H48: =$AI48/Presupuesto!$H$6*H$30 -> 6.4516129 | I48: =$AI48/Presupuesto!$H$6*I$30 -> 7.7419355 | J48: =$AI48/Presupuesto!$H$6*J$30 -> 9.0322581 | K48: =$AI48/Presupuesto!$H$6*K$30 -> 10.322581 | ... AH48: =$AI48/Presupuesto!$H$6*AH$30 -> 40 | AI48: =Presupuesto!K25 -> 40
B49: Costo Variable - Gasto Pega | C49: Uber Pega | D49: =$AI49/Presupuesto!$H$6*D$30 -> 7.6290323 | E49: =$AI49/Presupuesto!$H$6*E$30 -> 15.258065 | F49: =$AI49/Presupuesto!$H$6*F$30 -> 22.887097 | G49: =$AI49/Presupuesto!$H$6*G$30 -> 30.516129 | H49: =$AI49/Presupuesto!$H$6*H$30 -> 38.145161 | I49: =$AI49/Presupuesto!$H$6*I$30 -> 45.774194 | J49: =$AI49/Presupuesto!$H$6*J$30 -> 53.403226 | K49: =$AI49/Presupuesto!$H$6*K$30 -> 61.032258 | ... AH49: =$AI49/Presupuesto!$H$6*AH$30 -> 236.5 | AI49: =Presupuesto!K26 -> 236.5
B50: Costo Variable - Gasto Pega | C50: Tren - GoCard - Scooter Pega | D50: =$AI50/Presupuesto!$H$6*D$30 -> 3.1903226 | E50: =$AI50/Presupuesto!$H$6*E$30 -> 6.3806452 | F50: =$AI50/Presupuesto!$H$6*F$30 -> 9.5709677 | G50: =$AI50/Presupuesto!$H$6*G$30 -> 12.76129 | H50: =$AI50/Presupuesto!$H$6*H$30 -> 15.951613 | I50: =$AI50/Presupuesto!$H$6*I$30 -> 19.141935 | J50: =$AI50/Presupuesto!$H$6*J$30 -> 22.332258 | K50: =$AI50/Presupuesto!$H$6*K$30 -> 25.522581 | ... AH50: =$AI50/Presupuesto!$H$6*AH$30 -> 98.9 | AI50: =Presupuesto!K27 -> 98.9
B51: Costo Variable - Gasto Pega | C51: Parking - Otros Pega | D51: =$AI51/Presupuesto!$H$6*D$30 -> 3.883871 | E51: =$AI51/Presupuesto!$H$6*E$30 -> 7.7677419 | F51: =$AI51/Presupuesto!$H$6*F$30 -> 11.651613 | G51: =$AI51/Presupuesto!$H$6*G$30 -> 15.535484 | H51: =$AI51/Presupuesto!$H$6*H$30 -> 19.419355 | I51: =$AI51/Presupuesto!$H$6*I$30 -> 23.303226 | J51: =$AI51/Presupuesto!$H$6*J$30 -> 27.187097 | K51: =$AI51/Presupuesto!$H$6*K$30 -> 31.070968 | ... AH51: =$AI51/Presupuesto!$H$6*AH$30 -> 120.4 | AI51: =Presupuesto!K28 -> 120.4
B52: Costo Variable - Personales | C52: Otros Personales | D52: =$AI52/Presupuesto!$H$6*D$30 -> 4.8387097 | E52: =$AI52/Presupuesto!$H$6*E$30 -> 9.6774194 | F52: =$AI52/Presupuesto!$H$6*F$30 -> 14.516129 | G52: =$AI52/Presupuesto!$H$6*G$30 -> 19.354839 | H52: =$AI52/Presupuesto!$H$6*H$30 -> 24.193548 | I52: =$AI52/Presupuesto!$H$6*I$30 -> 29.032258 | J52: =$AI52/Presupuesto!$H$6*J$30 -> 33.870968 | K52: =$AI52/Presupuesto!$H$6*K$30 -> 38.709677 | ... AH52: =$AI52/Presupuesto!$H$6*AH$30 -> 150 | AI52: =Presupuesto!K29 -> 150
B53: Costo Variable - Personales | C53: Libros - Cursos | D53: =$AI53/Presupuesto!$H$6*D$30 -> 4.1612903 | E53: =$AI53/Presupuesto!$H$6*E$30 -> 8.3225806 | F53: =$AI53/Presupuesto!$H$6*F$30 -> 12.483871 | G53: =$AI53/Presupuesto!$H$6*G$30 -> 16.645161 | H53: =$AI53/Presupuesto!$H$6*H$30 -> 20.806452 | I53: =$AI53/Presupuesto!$H$6*I$30 -> 24.967742 | J53: =$AI53/Presupuesto!$H$6*J$30 -> 29.129032 | K53: =$AI53/Presupuesto!$H$6*K$30 -> 33.290323 | ... AH53: =$AI53/Presupuesto!$H$6*AH$30 -> 129 | AI53: =Presupuesto!K30 -> 129
...
